{
  "status": "failed",
  "error": "'dict' object has no attribute 'add_error'",
  "traceback": "Traceback (most recent call last):\n  File \"/Users/sankar/sankar/courses/agentic-ai/sv-agentic-ai/AI_NEWS_LANGGRAPH/src/ai_news_langgraph/nodes_v2.py\", line 98, in initialize_workflow\n    topics_config = self._load_topics_config(state.topics_path)\n                                             ^^^^^^^^^^^^^^^^^\nAttributeError: 'dict' object has no attribute 'topics_path'\n\nDuring handling of the above exception, another exception occurred:\n\nTraceback (most recent call last):\n  File \"/Users/sankar/sankar/courses/agentic-ai/sv-agentic-ai/AI_NEWS_LANGGRAPH/src/ai_news_langgraph/workflow.py\", line 208, in execute\n    final_state = await self._execute_standard(\n                  ^^^^^^^^^^^^^^^^^^^^^^^^^^^^^\n  File \"/Users/sankar/sankar/courses/agentic-ai/sv-agentic-ai/AI_NEWS_LANGGRAPH/src/ai_news_langgraph/workflow.py\", line 264, in _execute_standard\n    final_state_dict = await self.graph.ainvoke(\n                       ^^^^^^^^^^^^^^^^^^^^^^^^^\n  File \"/Users/sankar/sankar/courses/agentic-ai/sv-agentic-ai/AI_NEWS_LANGGRAPH/.venv/lib/python3.12/site-packages/langgraph/pregel/main.py\", line 3154, in ainvoke\n    async for chunk in self.astream(\n  File \"/Users/sankar/sankar/courses/agentic-ai/sv-agentic-ai/AI_NEWS_LANGGRAPH/.venv/lib/python3.12/site-packages/langgraph/pregel/main.py\", line 2976, in astream\n    async for _ in runner.atick(\n  File \"/Users/sankar/sankar/courses/agentic-ai/sv-agentic-ai/AI_NEWS_LANGGRAPH/.venv/lib/python3.12/site-packages/langgraph/pregel/_runner.py\", line 295, in atick\n    await arun_with_retry(\n  File \"/Users/sankar/sankar/courses/agentic-ai/sv-agentic-ai/AI_NEWS_LANGGRAPH/.venv/lib/python3.12/site-packages/langgraph/pregel/_retry.py\", line 137, in arun_with_retry\n    return await task.proc.ainvoke(task.input, config)\n           ^^^^^^^^^^^^^^^^^^^^^^^^^^^^^^^^^^^^^^^^^^^\n  File \"/Users/sankar/sankar/courses/agentic-ai/sv-agentic-ai/AI_NEWS_LANGGRAPH/.venv/lib/python3.12/site-packages/langgraph/_internal/_runnable.py\", line 706, in ainvoke\n    input = await asyncio.create_task(\n            ^^^^^^^^^^^^^^^^^^^^^^^^^^\n  File \"/Users/sankar/sankar/courses/agentic-ai/sv-agentic-ai/AI_NEWS_LANGGRAPH/.venv/lib/python3.12/site-packages/langgraph/_internal/_runnable.py\", line 474, in ainvoke\n    ret = await self.afunc(*args, **kwargs)\n          ^^^^^^^^^^^^^^^^^^^^^^^^^^^^^^^^^\n  File \"/Users/sankar/sankar/courses/agentic-ai/sv-agentic-ai/AI_NEWS_LANGGRAPH/.venv/lib/python3.12/site-packages/langchain_core/runnables/config.py\", line 611, in run_in_executor\n    return await asyncio.get_running_loop().run_in_executor(\n           ^^^^^^^^^^^^^^^^^^^^^^^^^^^^^^^^^^^^^^^^^^^^^^^^^\n  File \"/Users/sankar/.local/share/uv/python/cpython-3.12.11-macos-aarch64-none/lib/python3.12/concurrent/futures/thread.py\", line 59, in run\n    result = self.fn(*self.args, **self.kwargs)\n             ^^^^^^^^^^^^^^^^^^^^^^^^^^^^^^^^^^\n  File \"/Users/sankar/sankar/courses/agentic-ai/sv-agentic-ai/AI_NEWS_LANGGRAPH/.venv/lib/python3.12/site-packages/langchain_core/runnables/config.py\", line 602, in wrapper\n    return func(*args, **kwargs)\n           ^^^^^^^^^^^^^^^^^^^^^\n  File \"/Users/sankar/sankar/courses/agentic-ai/sv-agentic-ai/AI_NEWS_LANGGRAPH/src/ai_news_langgraph/nodes_v2.py\", line 110, in initialize_workflow\n    state.add_error(f\"Initialization failed: {str(e)}\")\n    ^^^^^^^^^^^^^^^\nAttributeError: 'dict' object has no attribute 'add_error'\nDuring task with name 'initialize' and id 'e62902b3-f08e-f86a-d251-639399e8c5da'\n",
  "thread_id": "thread_1760305912.126907"
}